Workbook

Sheet Vashundhar_1
A1: VASUNDHRA1- January-26 | I1: 1
A2: S.NO | B2: NAME | C2: ADDRESS | D2: PHONE NO | E2: Requirement | F2: B | G2: C | H2: Milk Schedule | I2: Extra
A3: 1 | B3: Vasundhra valley | C3: VASUDHA- D3 | D3: 8178029153 | E3: 2B | F3: 2
A4: 2 | B4: Dolly Taneja | C4: Pragya Kunj -1111 | D4: 7009497587 | E4: 2 | F4: 2
A5: 3 | C5: Pragya Kunj-4074 | D5: 7065590072 | E5: 1b | F5: 1
A6: 4 | C6: Pragya Kunj -2109 | D6: 8510966648 | E6: 2B | F6: 0 | H6: call
A7: 5 | B7: SUMATI CHAUHAN | C7: ADERSH APP-2224 | D7: 9818128319 | E7: 1A2B | F7: 1
A8: 6 | B8: Sunaina | C8: 4B - 3169 | D8: 9650853895 | E8: 2B | F8: 0
A9: 7 | B9: pk-3070 | C9: Shiv ganga 1133 | D9: 9953309810 | E9: 1C | G9: 0 | H9: mon ko
A10: 8 | B10: Bibha thakur | C10: shivganga-2168 | D10: 9871300336 | E10: 1B | F10: 1 | H10: 250g paneer
A11: 9 | C11: shivganga-3165 | D11: 9718711407 | E11: 2A1B | F11: 0 | H11: call
A12: 10 | C12: shivganga-3133 | D12: 9911912160 | E12: 1C | G12: 0 | H12: call
A13: 11 | B13: Shiksha Apparment | C13: sec-6-H1-5 | D13: 9625540018 | E13: 2B | F13: 2
A14: 12 | C14: 2C-193 | D14: 8882604579 | E14: 1C | G14: 1
A15: 13 | C15: 2c-306-gf | D15: 9953410100 | E15: 2.5B | F15: 2.5
A16: 14 | C16: 2C-306-F1 | D16: 9212884853 | E16: 2B | F16: 2
A17: 15 | C17: 2C-306-SF | D17: 9910608673 | E17: 1.5B | F17: 1.5
A18: 16 | C18: 2C-361FF | D18: 9811883345 | E18: 1A2B | F18: 0
A19: 17 | C19: 2B-1507-Shri laxmi apr. | D19: 9811963708 | E19: 1B | F19: 1
A20: 18 | B20: Akash ganga | C20: Akash ganga-3028 | D20: 8920695146 | E20: 1.5 | F20: 1.5
A21: 19 | C21: Akash ganga-4026 | D21: 9999160597 | E21: 1C | G21: 0 | H21: call
A22: 20 | B22: akansha | C22: 2B-461 GF | D22: 6397861741 | E22: 1B | F22: 1
A23: 21 | B23: ALKA | C23: 2B-461 ff | D23: 9871537267 | E23: 2b | F23: 2
A24: 22 | B24: GULSHER ALI | C24: 4B -1095 | D24: 9990489961 | E24: 2B | F24: 2
A25: 23 | C25: 2B-442-3rd floor | D25: 9501434355 | E25: .5c | G25: 0.5
A26: 24 | C26: 2B-442-FF | D26: 8650904848 | E26: .5B | F26: 0
A27: 25 | C27: 2B-442-gf | D27: 9027648080 | E27: .5B | F27: 0.5
A28: 26 | C28: 2B-686-TF | D28: 9910991241 | E28: 1c | G28: 0 | H28: call
A29: 27 | C29: 2B-684 | D29: 8448348222 | E29: 1b | F29: 1
A30: 28 | C30: 2B-688 | D30: 9810007295 | E30: 1A2C | G30: 2
A31: 29 | C31: 2B-406 | D31: 9389878093 | E31: 2B | F31: 2
A32: 30 | C32: 4A-2021 | D32: 9899214690 | E32: 2B | F32: 2
A33: 31 | C33: 4A-2032 | D33: 9319344490 | E33: 1B | F33: 0 | H33: call
A34: 32 | C34: 4A-1060 | D34: 9058052730 | E34: 3b | F34: 3
A35: 33 | B35: 15-1140 | C35: LAXMAN | D35: 8882967949 | E35: .5B | F35: 0.5
A36: 34 | C36: 1-196-GF | D36: 9711302012 | E36: 2B | F36: 2
A37: 35 | C37: SUMIT DEALER | E37: 2B | F37: 2
E38: TOTAL | F38: =SUM(F3:F37) -> 35.5 | G38: =SUM(G3:G37) -> 3.5

Sheet Vashundhar_2
A1: Vashundhar_2 DELIVERY SHEET: January-26 | I1: 1
B2: NAME | C2: ADDRESS | D2: phone no | E2: Requirement | F2: B | G2: C | H2: Milk Schedule | I2: Extra
A3: 1 | C3: Judge colony9/58 GF | D3: 9899220331 | E3: 2B | F3: 2
A4: 2 | C4: 17E-622 konark | D4: 9560093125 | E4: 1c | G4: 1
A5: 3 | C5: KONARK E-428 | D5: 9278261027 | E5: 3B | F5: 3
A6: 4 | C6: KONARK E-625 | D6: 9212022123 | E6: 1c | G6: 1
A7: 5 | C7: UNI29 | D7: 9628569374 | E7: 1B1C | F7: 1 | G7: 1
A8: 6 | C8: UNI27 | D8: 9971436366 | E8: 2A0 | F8: 2
A9: 7 | C9: Shikhar Enclave 903 | D9: 8527752116 | E9: 2b | F9: 2
A10: 8 | B10: SHALESH VATS | C10: 17G-405-SF/17G-104 | D10: 9910416500 | E10: 1.5B | F10: 1.5
A11: 9 | B11: Bhupendra Singh | C11: 17C-417 | D11: 9990827204 | E11: 1B | F11: 1
A12: 10 | C12: 16B-422-1-FF | D12: 9350216840 | E12: 1B | F12: 1
A13: 11 | C13: 16b-425gf | D13: 8445804457 | E13: 1.5B | F13: 1.5
A14: 12 | B14: Sudhir ji | C14: Green view H-140 | D14: 9810094119 | E14: 2C | G14: 2
A15: 13 | C15: Green view H-309 | D15: 7065456864 | E15: 1B | F15: 1
A16: 14 | C16: 9/2/13/UGF2 | D16: 9868703536 | E16: 1B | F16: 1
A17: 15 | C17: 9/2/7-UG1 | D17: 9205866388 | E17: 1B | F17: 2 | H17: .5KG KHOYA,1bottle
A18: 16 | C18: 15-71-gf | D18: 9599956673 | E18: 1B | F18: 0
A19: 17 | C19: 15-15 | D19: 9868579737 | E19: 1B | F19: 1
A20: 18 | C20: MIGSUN-1610 | D20: 8851362151 | E20: 1B | F20: 1
A21: 19 | C21: MIGSUN-1612 | D21: 7503904417 | E21: 1C | G21: 1
A22: 20 | B22: D-607 SHIFT | C22: Drona Giri Sec 11-f420 | D22: 9213045667 | E22: 3A0B | F22: 0 | H22: CALL
A23: 21 | C23: Drona Giri Sec 11-D 312 | D23: 9868740030 | E23: 1B | F23: 0
A24: 22 | B24: NEW | C24: Drona Giri Sec 11-D 610 | D24: 9213758177 | E24: 1B | F24: 1
A25: 23 | B25: NEW | C25: 403 sai kripa | D25: 9650700776 | E25: 1B | F25: 0 | H25: CALL
A26: 24 | C26: Marlin-1606 | D26: 8802473666 | E26: 2C | G26: 2
A27: 25 | B27: SUMIT JI | C27: 9-1-FF2 JUDGE COLONY | D27: 9212172611 | E27: 1C | G27: 1
A28: 26 | C28: 9-1-SF2 | D28: 9811665151 | E28: 1B | F28: 1
A29: 27 | C29: AR ELYSIUM | D29: 9971081106 | E29: 2C | G29: 2 | H29: NEW
A30: 28 | C30: 13-25-SF | D30: 9999777969 | E30: 4B | F30: 4
A31: 29 | C31: 13-1053 | E31: 1A0C | G31: 0
A32: 30 | B32: Rajendra rawat | C32: 11-736-FF | D32: 9818423311 | E32: 1c | G32: 0 | H32: call
A33: 31 | B33: Sudha | C33: SEC 9 -1241GF | D33: 8368904071 | E33: 1b | F33: 1
A34: 32 | C34: 15-243-GF | D34: 7982970233 | E34: 1B | F34: 1
E35: TOTAL | F35: =SUM(F3:F34) -> 29 | G35: =SUM(G3:G34) -> 11

Sheet Vashundhra-3
A1: VASUNDHRA-3 DELIVERY SHEET: January-26 | I1: 1
A2: S.N | B2: NAME | C2: ADDRESS | D2: phone no | E2: Requirement | F2: B | G2: C | H2: Milk Schedule | I2: Extra
A3: 1 | B3: payment | C3: SEC-14 A/ ASHOKA SOCIETY HN-30 | D3: 9810583557 | E3: 2A1B | F3: 1 | H3: 2A1-A0A
A4: 2 | C4: SEC-14 A/ ASHOKA SOCIETY HN-31 | E4: 2B | F4: 0 | H4: new
A5: 3 | C5: SEC 14 -204 GF | D5: 8130777066 | E5: 1B | F5: 1 | H5: 1kg cream
A6: 4 | C6: SEC 14 -342 FF | D6: 9212295616 | E6: 2B | F6: 2
A7: 5 | C7: SEC-14-389 GF | D7: 6861896736 | E7: 1A0C | G7: 0 | H7: 11KO
A8: 6 | C8: 14/398 | D8: 8447604227 | E8: 2B | F8: 2
A9: 7 | B9: Aman tyagi | C9: 14-458-sf | D9: 8265871019 | E9: 1B | F9: 0
A10: 8 | C10: 14-458-gf | D10: 9810280172 | E10: 1B | F10: 1
A11: 9 | C11: 14-629-2 bell | D11: 9891619697 | E11: 1.5B | F11: 1.5
A12: 10 | C12: 10D-124-F1 | D12: 9918865888 | E12: 1.5B | F12: 0 | H12: CALL
A13: 11 | C13: 10D-37-FF1 | D13: 9643626211 | E13: 1B | F13: 1
A14: 12 | C14: SUMIT | D14: 9560313288 | E14: 2B | F14: 5
A15: 13 | C15: CHOTELAL | D15: 9958173450 | E15: 1B | F15: 1
A16: 14 | C16: CHOTELAL-2 | E16: 1B | F16: 0 | H16: call
A17: 15 | C17: 2A-37 FF | D17: 9559563155 | E17: 1C | G17: 1
A18: 16 | C18: 5-824-FF | D18: 9999571553 | E18: 1B | F18: 1
A19: 17 | B19: 578-FF | C19: Sec 5-582gf | D19: 9971703677 | E19: 1B | F19: 0
A20: 18 | B20: 575 | C20: 5-802 ff | D20: 9990314140 | E20: 1b | F20: 1
A21: 19 | B21: kusagr | C21: 5-855-sf | D21: 9358052210 | E21: 1.5b | F21: 1.5
A22: 20 | B22: 589 | C22: 5-859 ff | D22: 9212222234 | E22: 2A1C | G22: 0
A23: 21 | C23: 5-869-SF | D23: 9212222235 | E23: 2C | G23: 2
A24: 22 | B24: Rashi Sharma | C24: 5-995-GF | D24: 8630919252 | E24: 1C | G24: 1
A25: 23 | C25: 5-1028-GF | D25: 9716352032 | E25: 3c | G25: 3
A26: 24 | C26: 5-1028-SF | D26: 9555912750 | E26: 1C | G26: 1
A27: 25 | C27: 5-1108-GF | D27: 8010261200 | E27: 1C | G27: 1
A28: 26 | C28: 5-1114-sf | D28: 9650431475 | E28: 2C | F28: 1 | G28: 2
A29: 27 | C29: 5-1121-SF2 | D29: 9313284176 | E29: 1B | F29: 1
A30: 28 | C30: 5-1243-ugf | E30: 1B | F30: 0 | H30: call
A31: 29 | C31: Sec 3/1049-sf | D31: 7830512000 | E31: 1B | F31: 0 | H31: collct bottles,call
A32: 30 | C32: Sec 3/1339 -GF | D32: 9650187600 | E32: 1B | F32: 1
A33: 31 | C33: Sec 3/1345-GF | D33: 8800103483 | E33: 1.5B | F33: 1.5
A34: 32 | C34: GNC Greenwood C705 | D34: 9999039307 | E34: 1b | F34: 1
A35: 33 | C35: GNC Greenwood C901 | D35: 9810408304 | E35: 3B | F35: 3
A36: 34 | C36: SG Homes A-701 | D36: 8004939465 | E36: 2B | F36: 0
A37: 35 | C37: SG Homes C1312A | D37: 9540066880 | E37: 1B | F37: 1
A38: 36 | B38: 686tf | C38: Ksn Square-1302 | D38: 9910991241 | E38: 1C | G38: 1 | H38: NEW
A39: 37 | C39: 415 PATRAKAR Socitey | D39: 9711733186 | E39: 1B | F39: 1
A40: 38 | C40: doc parck B-102 | D40: 9810647473 | E40: 1A2B | F40: 2
...

Sheet Shalimar_Ext
A1: Shalimar_Ext DELIVERY SHEET: January-26 | I1: 1
A2: S.N | B2: NAME | C2: ADDRESS | D2: phone no | E2: Requirement | F2: B | G2: C | H2: Milk Schedule | I2: Extra
A3: 1 | C3: D2-703 | D3: 8700196116 | E3: 1B | F3: 1
A4: 2 | C4: SAVIOUR PARK-D1-1104 | D4: 9958897368 | E4: 3B | F4: 3
A5: 3 | C5: Plot 14-102 shalimar | D5: 9818921234 | E5: 2B | F5: 2 | H5: 100 GM PNEER
A6: 4 | B6: R.N Verma | C6: Flat no F1 Plot 5or6 Shalimar EX 4 | D6: 9818120285 | E6: 1C | G6: 1
A7: 5 | C7: Flat no.H3 Plot 5or6 Shalimar EX 4 | D7: 9811447114 | E7: 2C | G7: 0 | H7: NEW
A8: 6 | C8: F302-5/51 SEC5 Rajender NGR | D8: 9650924040 | E8: 2C | G8: 2
A9: 7 | C9: 11 / 56 SECTOR -3 RAJENDER NGR | D9: 7044206797 | E9: 1B | F9: 1
A10: 8 | C10: SRIDHA VILLA T3-S1 | D10: 8448938134 | E10: 2B | F10: 2
A11: 9 | C11: 143 FB LAJPAT NAGAR GF | D11: 9871186333 | E11: 1C | G11: 1
A12: 10 | C12: 143 FB LAJPAT NAGAR ff | D12: 9560812371 | E12: 2A1C | G12: 2 | H12: 250mkhn1.5ghi1pnr
A13: 11 | C13: 126fb Lajpat nagar | D13: 9999933584 | E13: 1.5c | G13: 1.5
A14: 12 | C14: 62FB BLOCK F | D14: 8851410101 | E14: 1C | G14: 1
A15: 13 | C15: 11-A9--102 Rajindra nagar | D15: 9210769610 | E15: 2C | G15: 2
A16: 14 | C16: 54 SWAROOP PARK gf | D16: 9999875999 | E16: 1B | F16: 1
A17: 15 | C17: 54 SWAROOP PARK FF | D17: 9599263026 | E17: 1B | F17: 1
A18: 16 | C18: Girdhar enclave-74- | D18: 8920765211 | E18: 1B1C | F18: 1 | G18: 0
A19: 17 | C19: samim bhai | D19: 9990202929 | E19: 1B | F19: 1
A20: 18 | C20: 16A-512 | D20: 7838481624 | E20: 1.5C | G20: 1.5 | H20: NEW
A21: 19 | C21: 12-418-tf | D21: 7838602829 | E21: 1.5C | G21: 1.5
A22: 20 | C22: 12-418-UGF2 | D22: 9873481343 | E22: 1b | F22: 0 | H22: CALL
A23: 21 | C23: 10C-15FF | D23: 9911142213 | E23: 2B | F23: 2
A24: 22 | C24: 10C-14SF | D24: 8743939067 | E24: 2B | F24: 2 | H24: ring bell
A25: 23 | C25: 10C-16FF | D25: 9540951262 | E25: 1A2B | F25: 1
A26: 24 | C26: 10A-02-UNCLE | D26: 9871836085 | E26: 4B | F26: 4
A27: 25 | C27: sahibabad | D27: 9971338754 | E27: 1b | F27: 1
A28: 26 | B28: JYOTI | C28: S. BAD-1 | D28: 7982123588 | E28: 1.5B | F28: 1
A29: 27 | C29: SANDEEP | D29: 8510032710 | E29: 1B | F29: 1
A30: 28 | C30: jitendra singh | D30: 8700293135 | E30: 1B | F30: 0 | H30: CALL
A31: 29 | B31: SANJU | C31: S. BAD-2 | D31: 8287371065 | E31: 2b | F31: 2
A32: 30 | B32: SHIVANGI | C32: S. BAD-3 | D32: 8979367971 | E32: 2.5C | G32: 2.5
A33: 31 | B33: RAJU TOMER | C33: S. BAD-6 | D33: 7065219625 | E33: 2B | F33: 2
A34: 32 | B34: SHAVNI | C34: S. BAD-7 | D34: 7011542605 | E34: 1B | F34: 1
A35: 33 | B35: Ranjeta | C35: S. BAD-8 | D35: 9315613920 | E35: .5C | G35: 0.5
A36: 34 | C36: jonty | D36: 8076342751 | E36: 2b | F36: 2
A37: 35 | C37: Nisha | D37: 6398364185 | E37: 1B | F37: 1
A38: 36 | B38: Vishwajeet | C38: Shivani hotel | D38: 8826782512 | E38: 1.5b | F38: 1.5
E39: TOTAL | F39: =SUM(F3:F38) -> 34.5 | G39: =SUM(G3:G38) -> 16.5

Sheet Vaishali_OLD
A1: VAISHALI OLD DELIVERY SHEET: January-26 | I1: 1
A2: S.N | B2: NAME | C2: ADDRESS | D2: Phone no | E2: Requirement | F2: B | G2: C | H2: Milk Schedule | I2: Extra
A3: 1 | C3: sagar yadav | D3: 7303434199 | E3: 1.5b | F3: 2.5
A4: 2 | C4: LAVISH YADAV | E4: .5b | F4: 0.5 | H4: 16SE1
A5: 3 | C5: HEMA | E5: .5B | F5: 0.5
A6: 4 | B6: RINKLE SINGH | C6: RINKLE SINGH | D6: 8295578551 | E6: .5B | F6: 0.5
A7: 5 | C7: ROSHAN | E7: 1b | F7: 1
A8: 6 | C8: PIYUSH | E8: 1b | F8: 1
A9: 7 | C9: sunil yadav | E9: 3b | F9: 3
A10: 8 | C10: Alam | E10: 1.5B | F10: 1.5
A11: 9 | C11: jashveer yadav | D11: 9315946625 | E11: 1B | F11: 1 | H11: new
A12: 10 | B12: Rattan Singh | C12: 6/36/S2 | D12: 9313489432 | E12: 2B | F12: 3 | H12: 250g khoya
A13: 11 | C13: 6/55/S1 | D13: 7906292994 | E13: 2B | F13: 2
A14: 12 | C14: 6-54-301 | D14: 9582919520 | E14: 1.5c | G14: 0
A15: 13 | C15: 6-54-101 | D15: 8630263505 | E15: 1B | F15: 1 | H15: .5Klaknd,ladu,brfi nryl
A16: 14 | C16: 6-101-s1 | D16: 991053038 | E16: 1A2B | F16: 1
A17: 15 | B17: 166-f3 | C17: Sushil 6/178/S2 | D17: 8447777798 | E17: 1.5C | G17: 1.5
A18: 16 | C18: Saurabh 6/74/202 | D18: 8826539130 | E18: 1B | F18: 1
A19: 17 | C19: 6-74-302 | D19: 9068227069 | E19: .5b | F19: 0 | H19: call
A20: 18 | C20: 6/95/F3/106-S1 | D20: 9711861864 | E20: 2B | F20: 0 | H20: 21ko
A21: 19 | C21: 6-50-f4 | E21: 1b | F21: 1 | H21: new
A22: 20 | B22: ARVIND KUMAR | C22: 6/175/204 | D22: 9313968927 | E22: 1B | F22: 1
A23: 21 | C23: 6/175/203 | D23: 8826291789 | E23: .5C | G23: 0.5
A24: 22 | C24: 6/63/202 | D24: 8447722734 | E24: 2.5b1.5c | F24: 2.5 | G24: 1.5
A25: 23 | B25: 175-401 | C25: 6/193/S2 | E25: 1A0B | F25: 0
A26: 24 | C26: Rahul Singh 6/78/F1 | E26: 3B | F26: 0 | H26: CALL
A27: 25 | C27: 6-171-S2 | D27: 9811961968 | E27: 2B | F27: 0
A28: 26 | C28: 6-171-S3 | E28: 1.5B | F28: 0
A29: 27 | C29: 6-140-g4 | D29: 9953727074 | E29: 1b | F29: 1
A30: 28 | C30: 6-149-303 | E30: 1A0B | F30: 0 | H30: NEW
A31: 29 | B31: 52-SF2 | C31: 6/60/TF | E31: 1B | F31: 1
A32: 30 | C32: 6-98-s4 | D32: 8920259211 | E32: 1.5C,1BA0 | F32: 0 | G32: 1.5
A33: 31 | C33: 6/66/105 | E33: 2b | F33: 0 | H33: CALL
A34: 32 | B34: R.K TOMER | C34: 6-9-ff1 | D34: 9654848959 | E34: 1A2B | F34: 1
A35: 33 | C35: 6/212-g2 | D35: 9818823352 | E35: 1B | F35: 1
A36: 34 | C36: 6-121-G1 | E36: .5B | F36: 0.5
A37: 35 | C37: 6-2-26-GF | D37: 9718756611 | E37: 1.5B | F37: 1.5
A38: 36 | B38: ravipal | C38: 6-2-26-ugf1 | D38: 7778997525 | E38: 1.5C | G38: 1.5
A39: 37 | C39: 6-2-27-gf | E39: 1C | G39: 1 | H39: NEW
A40: 38 | C40: 6_2-30 | D40: 7011465702 | E40: 1c | G40: 1
...

Sheet Rajnagar_Ext
A1: RAJNAGAR EXT. DELIVERY SHEET: January-26 | J1: 1
A2: S.N | B2: NAME | C2: ADDRESS | D2: phone no | E2: Requirement | F2: B | G2: GC | H2: C | J2: Extra
A3: 1 | B3: kapil | C3: 16b-422 ff | D3: 9717637423 | E3: .5C | G3: 0.5 | H3: 0.5
A4: 2 | C4: 16B/2025/FF | D4: 9458664442 | E4: 1B | F4: 0
A5: 3 | B5: 10C-176 | C5: 10D-2-GF | D5: 9015878932 | E5: 1B | F5: 1 | I5: .5KG KHOYA
A6: 4 | C6: Deepak Mama | D6: 9990949484 | E6: 3B | F6: 1
A7: 5 | C7: River Height T11-C-943 | E7: 1b | F7: 0 | I7: 12KO
A8: 6 | B8: Renu Bala | C8: River Height T11-C-241 | D8: 9811293792 | E8: 1B-1C | F8: 1 | H8: 1
A9: 7 | C9: SVD-D-1107 | D9: 9354144082 | E9: 1B | F9: 0 | I9: CALL
A10: 8 | B10: SVD-C-1002 | C10: SVD-D-113 | D10: 9711277112 | E10: 1B | F10: 1
A11: 9 | B11: KAPIL TYAGI | C11: SVD A-308 | D11: 9654090532 | E11: 2B | F11: 2
A12: 10 | B12: SHILPI | C12: SVD A-902 | D12: 9971816746 | E12: 2B | F12: 2
A13: 11 | C13: SVD-A-1410 | D13: 9828236802 | E13: 1B | F13: 0 | I13: call
A14: 12 | B14: Alka Choubey | C14: SVD-A-1501 | D14: 9827798975 | E14: 1b | F14: 1
A15: 13 | C15: Royal Santaza 706 | D15: 9873298515 | E15: 1b | F15: 0 | I15: call
A16: 14 | B16: Navin Kanaujia | C16: Ajnara Integrity B-1304 | D16: 8377002907 | E16: 2B | F16: 2
A17: 15 | B17: Shailza Sharma | C17: Officer city 1-J 301 | D17: 9643823690 | E17: 1B | F17: 2
A18: 16 | C18: Officer city 1-J -1303 | D18: 9310281113 | E18: 2.5 | H18: 0 | I18: 4KO
A19: 17 | B19: kapil sharma | C19: Officer city 1-J -1304 | D19: 9718324251 | E19: 2B | F19: 2
A20: 18 | B20: 1304 | C20: J-107 M | D20: 8506856525 | E20: 2B | F20: 2
A21: 19 | B21: Nehra ji | C21: Officer city 1 J 404 | D21: 9899111847 | E21: 1B | F21: 1
A22: 20 | C22: Officer city 1-S-709 | D22: 9639023866 | E22: 1b | F22: 1
A23: 21 | C23: Officer City-H-208 | D23: 6299195075 | E23: 1.5C | H23: 1.5
A24: 22 | C24: palm court P4-723 | E24: 3B | F24: 3 | I24: NEW
A25: 23 | B25: Ashinana | C25: palm court P4-724 | D25: 9818921234 | E25: 3B | F25: 0 | I25: CALL
A26: 24 | C26: GAUR H/364 | D26: 9599824835 | E26: 3B | F26: 0
A27: 25 | C27: Parshant tyagi,O-310,VVIP | E27: 3b | F27: 3
A28: 26 | B28: sg impration | C28: C-202-Aura chimera | D28: 9410009074 | E28: 2B | F28: 2
A29: 27 | C29: Charms castle F-806 | D29: 9873957380 | E29: 1.5C | H29: 0 | I29: 3KO
A30: 28 | C30: Charms castle B-402 | D30: 9958402908 | E30: 2b | F30: 0
A31: 29 | C31: classic residency j-B2-601 | D31: 9267950460 | E31: 1B1CA0 | F31: 0 | H31: 0
A32: 30 | C32: SG GRAND-E-105 | D32: 9953749084 | E32: 2B | F32: 0
A33: 31 | C33: SG GRAND-E-705 | D33: 9311276045 | E33: 1B | F33: 1
A34: 32 | B34: Nirmal Mishra | C34: D-1406,KM RESIDENCY | E34: 2AA1 | F34: 1
A35: 33 | B35: 16B-165 | C35: D-1401,KM RESIDENCY | D35: 9810650453 | E35: 1B | F35: 1
E36: TOTAL | F36: =SUM(F2:F35) -> 30 | G36: =SUM(G8:G35) -> 0 | H36: =SUM(H2:H35) -> 3

Sheet Vaishali_1
A1: VAISHALI 1 DELIVERY SHEET: January-26 | I1: 1
A2: S.N | B2: NAME | C2: ADDRESS | D2: phone no | E2: Requirement | F2: B | G2: C | H2: Milk Schedule | I2: Extra
A3: 1 | C3: 16B-195-FF | D3: 9958969641 | E3: 1.5B | F3: 0
A4: 2 | C4: Royal lengecy G-906 | D4: 9811599776 | E4: 2C | G4: 0 | H4: 2ko
A5: 3 | C5: Royal lengecy S-603 | D5: 9868806906 | E5: 1B | F5: 1
A6: 4 | C6: MAXCITZ ,T 12 -1201 | D6: 9560683231 | E6: 1C | F6: 1 | H6: 1KO
A7: 5 | B7: SATISH SHARMA | C7: MAXCITZ ,T10-502 | D7: 9873556852 | E7: 2B | F7: 2
A8: 6 | C8: MAXCITZ T-12 1401 | D8: 9971605526 | E8: 1C | G8: 1
A9: 7 | B9: Atul sharma | C9: CIVITECH T5-102 | D9: 7838777143 | E9: 2B | F9: 2 | G9: 1 | H9: 250PNEER
A10: 8 | C10: pearl square pockt10-g4 rm | D10: 8954401403 | E10: 1C | G10: 1
A11: 9 | B11: gate no.-2 | C11: pearl square pockt10-g3 rm | D11: 8076511480 | E11: 3B | F11: 3
A12: 10 | B12: Harish chauhan | C12: 4/334/D4th floor | D12: 9811738984 | E12: 2A1B | F12: 2
A13: 11 | B13: Avnish Mishra | C13: 4/334 D 1 | D13: 9930704030 | E13: 1C | G13: 1 | H13: ring bell
A14: 12 | C14: B2 4-334 | D14: 9630807134 | E14: 1B | F14: 0 | H14: CALL
A15: 13 | C15: VAISHALI SEC -2B -PLOT- 311 GF | D15: 7065858057 | E15: 1.5C | F15: 1.5
A16: 14 | C16: VAISHALI SEC -2B -PLOT- 311 FF | D16: 9560842982 | E16: 3b | F16: 0
A17: 15 | C17: VAISHALI SEC -2B -PLOT- 312 GF1 | D17: 7987296415 | E17: 1B | F17: 1 | H17: 250g paneer
A18: 16 | B18: neelu singh | C18: VAISHALI SEC -2B -PLOT- 312 GF2 | D18: 9718687453 | E18: 1b | F18: 1
A19: 17 | C19: VAISHALI SEC -2B -PLOT- 312 FF | D19: 9910625683 | E19: 1B | F19: 1
A20: 18 | C20: VAISHALI SEC -2B -PLOT- 313 gf | D20: 6307067498 | E20: 1B | F20: 1
A21: 19 | B21: 3-718 | C21: Vaishali, Sec-2-27 | D21: 9999228951 | E21: 2b | F21: 3
A22: 20 | C22: 2-138D-SF | D22: 9891086355 | E22: 2B | F22: 2
A23: 21 | C23: 1-122-SF | D23: 9910430259 | E23: 1A0 | F23: 0 | H23: CALL
A24: 22 | B24: 719GF | C24: Vaishali, Sec-3-773FF | D24: 9354744624 | E24: 2b | F24: 2
A25: 23 | C25: vaishali, Sec -3,726-GF | D25: 7983466763 | E25: 1B | F25: 0
A26: 24 | C26: Jaypuria Society 68-SF Kosambi | D26: 9811147367 | E26: 2A3B | F26: 1
A27: 25 | C27: Jaypuria Society 78 A Kosambi | D27: 8800399384 | E27: 1b | F27: 0
A28: 26 | C28: Jaypuria Society H.N-3 | D28: 8010514822 | E28: 2c | G28: 0 | H28: CALL
A29: 27 | C29: Kosambi Sail Society A-1106 | D29: 9968605431 | E29: 1b | F29: 0 | H29: CALL
A30: 28 | C30: Kosambi Sail Society A-1204 | D30: 7976259706 | E30: 1C | G30: 0
A31: 29 | C31: cloude 9 | E31: 1c | G31: 1
A32: 30 | C32: Gardenia green,A-103 | D32: 9350885628 | E32: 2B | F32: 2
E33: TOTAL | F33: =SUM(F3:F32) -> 26.5 | G33: =SUM(G3:G32) -> 5

Sheet Shop
A1: Shop Customer DELIVERY SHEET: January-26 | I1: 1
A2: S.N | B2: NAME | C2: ADDRESS | D2: phone no | E2: Requirement | F2: B | G2: C | H2: Milk Schedule | I2: Extra
A3: 1 | B3: kamal bhaiya | G3: 2
A4: 2 | B4: 16b/230 | E4: 1b | F4: 1
A5: 3 | B5: 16B-231FF | F5: 0 | H5: call
A6: 4 | B6: Aunty16b/208 | G6: 1.5
A7: 5 | B7: 16b/226 | E7: 1A0 | F7: 1
A8: 6 | C8: royal G-803 | D8: 9818114194 | E8: 1.5B | F8: 1.5
A9: 7 | B9: kamal uncle | C9: royal regency | E9: 4B | F9: 3
A10: 8 | C10: 6-115-202 | E10: 1.5 | F10: 1.5
A11: 9 | C11: BHOLU TYAGI | E11: 1.5 | F11: 1.5
A12: 10 | C12: YAKUB ALI JI | D12: 9212116002 | E12: 2b | F12: 0
A13: 11 | C13: SANDEEP MILK | E13: 1B | F13: 1
A14: 12 | C14: FREED MALIK | D14: 8882534320 | E14: 1B | F14: 1.5
A15: 13 | C15: 10D-124-TF1 | E15: 2B | F15: 2 | G15: 0 | H15: CALL
A16: 14 | C16: Ritik | E16: 1B | F16: 1
A17: 15 | C17: sumit milk | E17: 1B | F17: 1
A18: 16 | C18: NCRB-45 | E18: 1B | F18: 1
A19: 17 | C19: Premlata | E19: 1B | F19: 1 | H19: 26 se
A20: 18 | B20: 16b-458 | C20: Rahmani | D20: 9891244104 | E20: .5c | F20: 0.5
E21: TOTAL | F21: =SUM(F3:F20) -> 18.5 | G21: =SUM(G3:G16) -> 3.5

Sheet Siddhart Vihar
A1: Siddhart Vihar DELIVERY SHEET: January-26 | I1: 1
A2: S.N | B2: NAME | C2: ADDRESS | D2: phone no | E2: Requirement | F2: B | G2: C | H2: Milk Schedule | I2: Extra
A3: 1 | B3: Goldan bhai | C3: Shipra Revira SRC 49C-SF | D3: 8587882781 | E3: 1B | F3: 1
A4: 2 | B4: KULDEEP SINGH | C4: JG-2 Aditya mega city | D4: 8375024088 | E4: 1B | F4: 0
A5: 3 | C5: Aditya mega city B-402 | D5: 9971072738 | E5: 3B | F5: 3
A6: 4 | B6: S.K.2-C2-117 | C6: D2-153 NK2 | D6: 9968412357 | E6: 2B | F6: 2
A7: 5 | C7: NK-1-376- GF1 | D7: 8375058809 | E7: 2B | F7: 2
A8: 6 | C8: NK-1-438-ugf | D8: 9910377339 | E8: .5CA0 | G8: 0.5
A9: 7 | B9: Sandhya Phore | C9: Niti Khand 3-581 SF | D9: 9136207374 | E9: 2b | F9: 0 | H9: call
A10: 8 | C10: Niti Khand 2-268-TF2 | D10: 9717111741 | E10: 3b | F10: 3
A11: 9 | C11: Niti Khand 3-41 gf | D11: 8077079969 | E11: 1B | F11: 1
A12: 10 | B12: Dr.Anandpal Singh | C12: Niti Khand 3-41 FF | D12: 9136207474 | E12: 4b | F12: 4
A13: 11 | C13: Shipra Shristi SEM B 810 | D13: 9654007470 | E13: 1B | F13: 0 | H13: MON-WED-FRI
A14: 12 | C14: sayagold-6-1604 | D14: 9811315816 | E14: 2A1B | F14: 2
A15: 13 | C15: sayagold-5-2301 | D15: 9899941084 | E15: 2B | F15: 2
A16: 14 | C16: SAYA ZENITH AHINSA-A1-208 | D16: 9910113992 | E16: 1A0 | F16: 0
A17: 15 | B17: Chitrasen Paridhi | C17: LA ROYAL S-1106 | D17: 9891707677 | E17: 1b | F17: 2
A18: 16 | B18: PALLAVI | C18: A-501 Aditya city | D18: 8826684440 | E18: 1.5C | G18: 1.5
A19: 17 | C19: Guard Aditya city | D19: 7210573323 | E19: 0.5b | F19: 0.5 | H19: guard
A20: 18 | C20: Guard Aditya city | E20: .5B | F20: 0.5
A21: 19 | C21: Gali-4-159 Abhaykhand-1 | D21: 8171945058 | E21: 1B1C | F21: 0 | G21: 0
A22: 20 | C22: GALI NO 3 | D22: 7056341649 | E22: 1C | G22: 1
A23: 21 | C23: Prateek grand P7-2402 | D23: 9958833292 | E23: 1A0B | F23: 1
A24: 22 | C24: ANIL | D24: 9319748522 | E24: 1B | F24: 2
A25: 23 | C25: GAUR Sirddhattm D540 | D25: 9911245981 | E25: 2B | F25: 2
A26: 24 | C26: GAUR Sirddhattm H-671 | D26: 9307460482 | E26: 1b | F26: 1
A27: 25 | C27: GAUR F-553 | D27: 7840875551 | E27: 2B | F27: 2
A28: 26 | C28: RAIL VIHAR-A-105 | D28: 9310523102 | E28: 2B | F28: 2
A29: 27 | C29: RAIL VIHAR-F-202 | D29: 9873199009 | E29: 1A0C | G29: 0
A30: 28 | C30: Arunima Palace B-608 | D30: 9136887616 | E30: .5b | F30: 0.5
A31: 29 | C31: Arunima Palace C1201 | D31: 8826726306 | E31: 1A0 | F31: 0
A32: 30 | C32: 1-504 | D32: 9711991430 | E32: 1b | F32: 1
A33: 31 | C33: 1-514-sf3 | D33: 8439978886 | E33: 1C | G33: 1 | H33: NEW
A34: 32 | C34: 1-523-ug1 | D34: 8449428988 | E34: 2b | F34: 2
A35: 33 | C35: 1-523-SF1 | D35: 9871122152 | E35: 1.5C | G35: 1.5
A36: 34 | B36: 581-SF | C36: 1-699-3RD FLOOR | D36: 9899366551 | E36: 2A1B | F36: 2
A37: 35 | C37: CHAI WALA | E37: 3B | F37: 3
E38: TOTAL | F38: =SUM(F3:F37) -> 41.5 | G38: =SUM(G3:G37) -> 5.5

Sheet Total
A1: B0TTEL OF SUPPLY
A2: Date | E2: 1 | F2: JAN | G2: 25
A3: S.NO. | B3: DELIVERY BOY | C3: B | D3: C | E3: TOTAL | F3: EMPTY | G3: BALANCE
A4: 1 | B4: Vasundhar 1 | C4: =Vashundhar_1!F38 -> 35.5 | D4: =Vashundhar_1!G38 -> 3.5 | E4: =D4+C4 -> 39 | F4: 44 | G4: =F4-E4 -> 5
A5: 2 | B5: Vasundhar 2 | C5: =Vashundhar_2!F35 -> 29 | D5: =Vashundhar_2!G35 -> 11 | E5: =D5+C5 -> 40 | F5: 40 | G5: =F5-E5 -> 0
A6: 3 | B6: VASHUNDHRA-3 | C6: ='Vashundhra-3'!F42 -> 31.5 | D6: ='Vashundhra-3'!G42 -> 12 | E6: =D6+C6 -> 43.5 | F6: 49 | G6: =F6-E6 -> 5.5
A7: 4 | B7: Shalimar_Ext | C7: =Shalimar_Ext!F39 -> 34.5 | D7: =Shalimar_Ext!G39 -> 16.5 | E7: =D7+C7 -> 51 | F7: 53 | G7: =F7-E7 -> 2
A8: 5 | B8: Rajnagar_Ext | C8: =Rajnagar_Ext!F36 -> 30 | D8: =Rajnagar_Ext!H36 -> 3 | E8: =D8+C8 -> 33 | F8: 34 | G8: =F8-E8 -> 1
A9: 6 | B9: Vaishali_OLD | C9: =Vaishali_OLD!F42 -> 31.5 | D9: =Vaishali_OLD!G42 -> 8.5 | E9: =D9+C9 -> 40 | F9: 31 | G9: =F9-E9 -> -9
A10: 7 | B10: Vaishali_1 | C10: =Vaishali_1!F33 -> 26.5 | D10: =Vaishali_1!G33 -> 5 | E10: =D10+C10 -> 31.5 | F10: 30 | G10: =F10-E10 -> -1.5
A11: 8 | B11: Shop | C11: =Shop!F21 -> 18.5 | D11: =Shop!G21 -> 3.5 | E11: =D11+C11 -> 22 | G11: =F11-E11 -> -22
A12: 9 | B12: Siddhart Vihar | C12: ='Siddhart Vihar'!F38 -> 41.5 | D12: ='Siddhart Vihar'!G38 -> 5.5 | E12: =D12+C12 -> 47 | G12: =F12-E12 -> -47
B13: Total | C13: =SUM(C4:C12) -> 278.5 | D13: =SUM(D4:D12) -> 68.5 | E13: =SUM(E4:E12) -> 347 | F13: =SUM(F4:F12) -> 281 | G13: =SUM(G4:G12) -> -66
